5. OUTPUT OF THE FOLLOWING PROGRAM.
  #include <iostream>  
#include <exception>  
using namespace std;  
class MyException : public exception{  
    public:  
        const char * what() const throw()  
        {  
            return "Attempted to divide by zero!\n";  
        }  
};  
int main()  
{  
    try  
    {  
        int x, y;  
        cout << "Enter the two numbers : \n";  
        cin >> x >> y;  
        if (y == 0)  
        {  
            MyException z;  
            throw z;  
        }  
        else  
        {  
            cout << "x / y = " << x/y << endl;  
        }  
    }  
    catch(exception& e)  
    {  
        cout << e.what();  
    }  
}  
// OUTPUT
Enter the two numbers :
44
56
x / y = 0
